Internal Server Error: /api/v1/account/approvals/
Traceback (most recent call last):
  File "C:\Data\EPA R9\GeoPlatform-Request-Tool\venv\lib\site-packages\django\core\handlers\exception.py", line 34, in inner
    response = get_response(request)
  File "C:\Data\EPA R9\GeoPlatform-Request-Tool\venv\lib\site-packages\django\core\handlers\base.py", line 115, in _get_response
    response = self.process_exception_by_middleware(e, request)
  File "C:\Data\EPA R9\GeoPlatform-Request-Tool\venv\lib\site-packages\django\core\handlers\base.py", line 113, in _get_response
    response = wrapped_callback(request, *callback_args, **callback_kwargs)
  File "C:\Data\EPA R9\GeoPlatform-Request-Tool\venv\lib\site-packages\django\views\decorators\csrf.py", line 54, in wrapped_view
    return view_func(*args, **kwargs)
  File "C:\Data\EPA R9\GeoPlatform-Request-Tool\venv\lib\site-packages\rest_framework\viewsets.py", line 114, in view
    return self.dispatch(request, *args, **kwargs)
  File "C:\Data\EPA R9\GeoPlatform-Request-Tool\venv\lib\site-packages\rest_framework\views.py", line 505, in dispatch
    response = self.handle_exception(exc)
  File "C:\Data\EPA R9\GeoPlatform-Request-Tool\venv\lib\site-packages\rest_framework\views.py", line 465, in handle_exception
    self.raise_uncaught_exception(exc)
  File "C:\Data\EPA R9\GeoPlatform-Request-Tool\venv\lib\site-packages\rest_framework\views.py", line 476, in raise_uncaught_exception
    raise exc
  File "C:\Data\EPA R9\GeoPlatform-Request-Tool\venv\lib\site-packages\rest_framework\views.py", line 502, in dispatch
    response = handler(request, *args, **kwargs)
  File "C:\Data\EPA R9\GeoPlatform-Request-Tool\venv\lib\site-packages\rest_framework\mixins.py", line 42, in list
    serializer = self.get_serializer(page, many=True)
  File "C:\Data\EPA R9\GeoPlatform-Request-Tool\venv\lib\site-packages\rest_framework\generics.py", line 110, in get_serializer
    return serializer_class(*args, **kwargs)
TypeError: 'NoneType' object is not callable
